<?xml version="1.0" ?>
<robot name="dami2" xmlns:xacro="http://ros.org/wiki/xacro">
  <xacro:include filename="$(find dami2_description)/urdf/common_properties.xacro"/>
  <xacro:include filename="$(find dami2_description)/urdf/dami2.gazebo.xacro"/>
<!--  <xacro:include filename="$(find dami_description)/urdf/insert_transmission.urdf.xacro"/>-->

  <link name="base_footprint"/>

  <joint name="base_joint" type="fixed">
    <parent link="base_footprint"/>
    <child link="base_link"/>
    <origin xyz="0.0 0.0 0.015" rpy="0 0 0"/>
  </joint>

  <link name="base_link">
    <visual>
      <origin xyz="0.0 0.0 0.0" rpy="0 0 0"/>
      <geometry>
        <mesh filename="package://dami2_description/meshes/bases/dami2_base.stl" scale="0.001 0.001 0.001"/>
      </geometry>
      <material name="light_black"/>
    </visual>

    <collision>
      <origin xyz="-0.0558386 0.0 0.04025" rpy="0 0 0"/>
      <geometry>
        <box size="0.223677 0.245578 0.0805"/>
      </geometry>
    </collision>

    <inertial>
      <origin xyz="0 0 0" rpy="0 0 0"/>
      <mass value="1.3729096e+00"/>
      <inertia ixx="8.7002718e-03" ixy="-4.7576583e-05" ixz="1.1160499e-04"
               iyy="8.6195418e-03" iyz="-3.5422299e-06"
               izz="1.4612727e-02" />
    </inertial>
  </link>

  <joint name="wheel_left_joint" type="continuous">
    <parent link="base_link"/>
    <child link="wheel_left_link"/>
    <origin xyz="0.0 0.138 0.01925" rpy="-1.57 0 0"/>
    <axis xyz="0 0 1"/>
  </joint>

<!--  <xacro:insert_velocity_transmission name="wheel_left_joint"/>-->

  <link name="wheel_left_link">
    <visual>
      <origin xyz="0 0 0" rpy="1.57 0 0"/>
      <geometry>
        <mesh filename="package://dami2_description/meshes/wheels/left_tire.stl" scale="0.001 0.001 0.001"/>
      </geometry>
      <material name="dark"/>
    </visual>

    <collision>
      <origin xyz="0 0 0" rpy="0 0 0"/>
      <geometry>
        <cylinder length="0.0176" radius="0.0325"/>
      </geometry>
    </collision>

    <inertial>
      <origin xyz="0 0 0" />
      <mass value="2.8498940e-02" />
      <inertia ixx="1.1175580e-05" ixy="-4.2369783e-11" ixz="-5.9381719e-09"
               iyy="1.1192413e-05" iyz="-1.4400107e-11"
               izz="2.0712558e-05" />
     </inertial>
  </link>

  <joint name="wheel_right_joint" type="continuous">
    <parent link="base_link"/>
    <child link="wheel_right_link"/>
    <origin xyz="0.0 -0.138 0.01925" rpy="-1.57 0 0"/>
    <axis xyz="0 0 1"/>
  </joint>

<!--  <xacro:insert_velocity_transmission name="wheel_right_joint"/>-->

  <link name="wheel_right_link">
    <visual>
      <origin xyz="0 0 0" rpy="1.57 0 0"/>
      <geometry>
        <mesh filename="package://dami2_description/meshes/wheels/right_tire.stl" scale="0.001 0.001 0.001"/>
      </geometry>
      <material name="dark"/>
    </visual>

    <collision>
      <origin xyz="0 0 0" rpy="0 0 0"/>
      <geometry>
        <cylinder length="0.0176" radius="0.0325"/>
      </geometry>
    </collision>

    <inertial>
      <origin xyz="0 0 0"/>
      <mass value="2.8498940e-02" />
      <inertia ixx="1.1175580e-05" ixy="-4.2369783e-11" ixz="-5.9381719e-09"
               iyy="1.1192413e-05" iyz="-1.4400107e-11"
               izz="2.0712558e-05" />
    </inertial>
  </link>

  <joint name="caster_back_right_joint" type="fixed">
    <parent link="base_link"/>
    <child link="caster_back_right_link"/>
    <origin xyz="-0.1376 -0.064 0.0" rpy="0 0 0"/>
  </joint>

  <link name="caster_back_right_link">
    <visual>
      <origin xyz="0 0 0" rpy="0 0 0"/>
      <geometry>
        <mesh filename="package://dami2_description/meshes/wheels/caster.stl" scale="0.001 0.001 0.001"/>
      </geometry>
      <material name="grey"/>
    </visual>

    <collision>
      <origin xyz="0 0 -0.0075" rpy="0 0 0"/>
      <geometry>
        <box size="0.025 0.009 0.015"/>
      </geometry>
    </collision>

    <inertial>
      <origin xyz="0 0 0" />
      <mass value="0.005" />
      <inertia ixx="0.001" ixy="0.0" ixz="0.0"
               iyy="0.001" iyz="0.0"
               izz="0.001" />
    </inertial>
  </link>

  <joint name="caster_back_left_joint" type="fixed">
    <parent link="base_link"/>
    <child link="caster_back_left_link"/>
    <origin xyz="-0.1376 0.064 0.0" rpy="0 0 0"/>
  </joint>

  <link name="caster_back_left_link">
    <visual>
      <origin xyz="0 0 0" rpy="0 0 0"/>
      <geometry>
        <mesh filename="package://dami2_description/meshes/wheels/caster.stl" scale="0.001 0.001 0.001"/>
      </geometry>
      <material name="grey"/>
    </visual>

    <collision>
      <origin xyz="0 0 -0.0075" rpy="0 0 0"/>
      <geometry>
        <box size="0.025 0.009 0.015"/>
      </geometry>
    </collision>

    <inertial>
      <origin xyz="0 0 0" />
      <mass value="0.005" />
      <inertia ixx="0.001" ixy="0.0" ixz="0.0"
               iyy="0.001" iyz="0.0"
               izz="0.001" />
    </inertial>
  </link>


  <joint name="imu_joint" type="fixed">
    <parent link="base_link"/>
    <child link="imu_link"/>
    <origin xyz="0.0 0.0 0.0705" rpy="0 0 0"/>
  </joint>


  <link name="imu_link">
    <visual>
      <origin xyz="0 0 0 " rpy="0 0 0" />
      <geometry>
        <mesh filename="package://dami2_description/meshes/sensors/imu.stl" scale="0.001 0.001 0.001"/>
      </geometry>
      <material name="dark"/>
    </visual>
  </link>

  <joint name="scan_joint" type="fixed">
    <parent link="base_link"/>
    <child link="base_scan"/>
    <origin xyz="-0.054025 0.0 0.14405" rpy="0 0 0"/>
  </joint>

  <link name="base_scan">
    <inertial>
      <mass value="0.114" />
      <origin xyz="0 0 0" />
      <inertia ixx="0.001" ixy="0.0" ixz="0.0"
               iyy="0.001" iyz="0.0"
               izz="0.001" />
    </inertial>
<!--    <visual>
      <origin xyz="0 0 0 " rpy="0 0 1.570796" />
      <geometry>
        <mesh filename="package://dami2_description/meshes/sensors/kinect.dae" scale="0.001 0.001 0.001"/>
      </geometry>
      <material name="dark"/>
    </visual>-->
    <collision>
      <origin xyz="0 0 0" rpy="0 0 0" />
      <geometry>
        <box size="0.07271 0.27794 0.0720"/>
      </geometry>
    </collision>
  </link>

<!--  <joint name="camera_depth_joint" type="fixed">
    <origin xyz="0 0.01235 0.0" rpy="0 0 0" />
    <parent link="camera_link" />
    <child link="camera_depth_frame" />
  </joint>

  <link name="camera_depth_frame"/>


  <joint name="camera_depth_optical_joint" type="fixed">
    <origin xyz="0 0 0" rpy="-1.5707963268 0 -1.5707963268" />
    <parent link="camera_depth_frame" />
    <child link="camera_depth_optical_frame" />
  </joint>

  <link name="camera_depth_optical_frame"/>

  <joint name="camera_rgb_joint" type="fixed">
    <origin xyz="0 -0.01235 0.0" rpy="0 0 0" />
    <parent link="camera_link" />
    <child link="camera_rgb_frame" />
  </joint>

  <link name="camera_rgb_frame"/>

  <joint name="camera_rgb_optical_joint" type="fixed">
    <origin xyz="0 0 0" rpy="-1.5707963268 0 -1.5707963268" />
    <parent link="camera_rgb_frame" />
    <child link="camera_rgb_optical_frame" />
  </joint>

  <link name="camera_rgb_optical_frame"/>
-->

</robot>
